<?xml version="1.0"?>
<robot name="LittleCar" xmlins:xacro="http://www.ros.org/wiki/xacro">
	<material name="blue">
		<color rgba="0 0 1 1"/>
	</material>

	<material name="black">
		<color rgba="0 0 1 1"/>
	</material>

	<!-- Base Link (Chassi) -->
	<link name="base_link">
		<visual>
			<geometry>
				<box size="0.5 0.2 0.1"/> <!-- Size of the Chassi -->
			</geometry>
			
			<material name="blue"/>
		</visual>
		
		<collision>
			<geometry>
				<box size="0.2 0.5 0.1"/>
			</geometry>
		</collision>
	</link>

	
	<!-- Wheels -->
	<link name="front_left_wheel">
		<visual>
			<geometry>
				<cylinder radius="0.05" length="0.05"/> 
			</geometry>
			
			<material name="black"/>
		</visual>
		
		<collision>
			<geometry>	
				<cylinder radius="0.05" length="0.05"/> 
			</geometry>
		</collision>
	</link>
	

	<joint name="front_left_wheel_joint" type="continuous">
		<parent link="base_link"/>
		<child link="front_left_wheel"/>
		<origin xyz="-0.1 0.25 -0.1" rpy="0 0 0"/>
		<axis xyz="0 0 1"/>
	</joint>

	


	<link name="front_right_wheel">
		<visual>
			<geometry>
				<cylinder radius="0.05" length="0.05"/> 
			</geometry>
			
			<material name="black"/>
		</visual>
		
		<collision>
			<geometry>	
				<cylinder radius="0.05" length="0.05"/> 
			</geometry>
		</collision>
	</link>
	
	
	

	<joint name="front_right_wheel_joint" type="continuous">
		<parent link="base_link"/>
		<child link="front_right_wheel"/>
		<origin xyz="0.1 0.25 -0.1" rpy="0 0 0"/>
		<axis xyz="0 0 1"/>
	</joint>


	<link name="rear_right_wheel">
		<visual>
			<geometry>
				<cylinder radius="0.05" length="0.05"/> 
			</geometry>
			
			<material name="black"/>
		</visual>
		
		<collision>
			<geometry>	
				<cylinder radius="0.05" length="0.05"/> 
			</geometry>
		</collision>
	</link>


	<joint name="rear_right_wheel_joint" type="continuous">
		<parent link="base_link"/>
		<child link="rear_right_wheel"/>
		<origin xyz="0.1 -0.25 -0.1" rpy="0 0 0"/>
		<axis xyz="0 0 1"/>
	</joint>

	<link name="rear_left_wheel">
		<visual>
			<geometry>
				<cylinder radius="0.05" length="0.05"/> 
			</geometry>
			
			<material name="black"/>
		</visual>
		
		<collision>
			<geometry>	
				<cylinder radius="0.05" length="0.05"/> 
			</geometry>
		</collision>
	</link>



	<joint name="rear_left_wheel_joint" type="continuous">
		<parent link="base_link"/>
		<child link="rear_left_wheel"/>
		<origin xyz="-0.1 -0.25 -0.1" rpy="0 0 0"/>
		<axis xyz="0 0 1"/>
	</joint>


</robot>
